Traceback (most recent call last):
  File "/home/nobre/Notebooks/.venv/lib/python3.13/site-packages/jupyter_core/utils/__init__.py", line 154, in wrapped
    asyncio.get_running_loop()
    ~~~~~~~~~~~~~~~~~~~~~~~~^^
RuntimeError: no running event loop

During handling of the above exception, another exception occurred:

Traceback (most recent call last):
  File "/home/nobre/Notebooks/.venv/lib/python3.13/site-packages/jupyter_cache/executors/utils.py", line 58, in single_nb_execution
    executenb(
    ~~~~~~~~~^
        nb,
        ^^^
    ...<4 lines>...
        **kwargs,
        ^^^^^^^^^
    )
    ^
  File "/home/nobre/Notebooks/.venv/lib/python3.13/site-packages/nbclient/client.py", line 1319, in execute
    return NotebookClient(nb=nb, resources=resources, km=km, **kwargs).execute()
           ~~~~~~~~~~~~~~~~~~~~~~~~~~~~~~~~~~~~~~~~~~~~~~~~~~~~~~~~~~~~~~~~~~~^^
  File "/home/nobre/Notebooks/.venv/lib/python3.13/site-packages/jupyter_core/utils/__init__.py", line 158, in wrapped
    return loop.run_until_complete(inner)
           ~~~~~~~~~~~~~~~~~~~~~~~^^^^^^^
  File "/usr/lib/python3.13/asyncio/base_events.py", line 725, in run_until_complete
    return future.result()
           ~~~~~~~~~~~~~^^
  File "/home/nobre/Notebooks/.venv/lib/python3.13/site-packages/nbclient/client.py", line 709, in async_execute
    await self.async_execute_cell(
        cell, index, execution_count=self.code_cells_executed + 1
    )
  File "/home/nobre/Notebooks/.venv/lib/python3.13/site-packages/nbclient/client.py", line 1062, in async_execute_cell
    await self._check_raise_for_error(cell, cell_index, exec_reply)
  File "/home/nobre/Notebooks/.venv/lib/python3.13/site-packages/nbclient/client.py", line 918, in _check_raise_for_error
    raise CellExecutionError.from_cell_and_msg(cell, exec_reply_content)
nbclient.exceptions.CellExecutionError: An error occurred while executing the following cell:
------------------
import os
import scripts.stationsLandUse as stLU

rootDir = os.getcwd()
file = 'Monitoramento_QAr_BR_latlon_2024.csv'
bufferSize = 1000
gdf = stLU.stationBuffers(rootDir,file,bufferSize)
gdf.head()
------------------


[31m---------------------------------------------------------------------------[39m
[31mTypeError[39m                                 Traceback (most recent call last)
[36mCell[39m[36m [39m[32mIn[1][39m[32m, line 7[39m
[32m      5[39m file = [33m'[39m[33mMonitoramento_QAr_BR_latlon_2024.csv[39m[33m'[39m
[32m      6[39m bufferSize = [32m1000[39m
[32m----> [39m[32m7[39m gdf = [43mstLU[49m[43m.[49m[43mstationBuffers[49m[43m([49m[43mrootDir[49m[43m,[49m[43mfile[49m[43m,[49m[43mbufferSize[49m[43m)[49m
[32m      8[39m gdf.head()

[31mTypeError[39m: stationBuffers() takes 2 positional arguments but 3 were given

